Workbook

Sheet Dashboard
B2: Singapore Public Playgrounds & Community Centres — Categorized Account
B4: TOTAL PLAYGROUND SITES ACCOUNTED | E4: PARK LAYER — NPARKS | H4: ESTATE LAYER — HDB & TOWN COUNCILS | K4: OTHER PUBLIC AGENCIES | N4: COMMUNITY CENTRES — PEOPLE'S ASSN
B5: 2108 | E5: 344 | H5: 1754 | K5: 10 | N5: 119
B6: Snapshot 17 Oct 2026 · official government datasets + OpenStreetMap community mapping + curated agency rows · playground account (Groups A–C) plus a People's Association community-centre amenity layer (Group D) · see Sources & Methodology for definitions and caveats
B8: Playgrounds by agency group | F8: Playgrounds by region (URA regions) | I8: Estate playgrounds — naming status
B9: Agency group | C9: Sites | F9: Region | G9: Sites | I9: Name status | J9: Sites
B10: A. NParks — Park Playgrounds | C10: 344 | F10: Central | G10: 575 | I10: Named | J10: 96
B11: B. HDB & Town Councils — Estate Playgrounds | C11: 1754 | F11: East | G11: 289 | I11: Unnamed (community-mapped) | J11: 1658
B12: C. Other Public Agencies | C12: 10 | F12: North | G12: 315
B13: Total | C13: 2108 | F13: North-East | G13: 449
F14: West | G14: 478 | I14: Community centres by region (Group D — amenity layer)
F15: Total | G15: 2106 | I15: Region | J15: CCs
I16: Central | J16: 39
I17: East | J17: 18
I18: North | J18: 13
I19: North-East | J19: 24
I20: Total | J20: 119
B21: Group D is an amenity layer on its own sheet — not part of the playground total. 58 of 119 CCs have a community-mapped playground within 150 m.
B69: Note: estate-layer counts are community-mapped (OpenStreetMap) and indicative of completeness; park-layer counts derive from the official NParks facility dataset; community centres derive from the official People's Association datasets. Details on the Sources & Methodology sheet.

Sheet Grouping Overview
B2: How the Playground Account Is Grouped
B4: The agency groups
B5: Group | C5: Who manages it | D5: What it covers | E5: Sites | F5: Data basis
B6: A. NParks — Park Playgrounds | C6: National Parks Board (NParks) | D6: Playgrounds inside Singapore's parks network — regional parks, neighbourhood parks, nature parks and park connectors. Includes flagship nature playgarden destinations (Admiralty Park, Coastal PlayGrove, Jurong Lake Gardens, Botanic Gardens). | E6: 344 | F6: Official NParks facility dataset (data.gov.sg) + OpenStreetMap
B7: B. HDB & Town Councils — Estate Playgrounds | C7: HDB & Town Councils | D7: Playgrounds within HDB housing estates, maintained by the 17 town councils (and by HDB for upgrading programmes). The classic 'downstairs playground' layer — from heritage mosaic designs to new thematic builds in BTO projects. | E7: 1754 | F7: OpenStreetMap (community-mapped) + named estate examples from editorial sources
B8: C. Other Public Agencies | C8: Other Public Agencies | D8: Playgrounds and dedicated play spaces run by other public bodies: Gardens by the Bay, National Heritage Board, National Library Board, SportSG (ActiveSG/Bukit Canberra), JTC, People's Association, Sentosa Development Corporation. | E8: 10 | F8: Curated from agency sites and editorial sources
B9: D. People's Association — Community Centres | C9: People's Association (statutory board) | D9: Community-centre amenity layer (not playgrounds): every PA community club at its current operating site — including clubs operating from temporary premises during redevelopment and new clubs under construction. PAssion WaVe outlets and co-located community outposts are footnoted on the Group D sheet. | E9: 119 | F9: Official PA 'Community Clubs' and 'Community Club / PAssion WaVe Outlet' datasets (data.gov.sg)
B10: Counts tie to the Master Inventory sheet row-for-row (verified on the Review sheet).
B12: Reading the layers together
B13: Singapore does not publish a single consolidated register of every playground, so this workbook combines three complementary layers: (1) the official NParks facility dataset for parks, (2) OpenStreetMap's community-mapped leisure=playground points for the estate layer, and (3) curated rows for agencies that do not publish location-level data.
B15: The result: roughly 2,100 playground sites accounted islandwide — 305 distinct sites from 387 official park facility records, 39 additional community-mapped park playgrounds, 1,754 estate playgrounds, and the curated other-agency layer — plus a Group D amenity layer of 119 People's Association community centres. The true estate count is higher; OSM completeness is good in newer towns and thinner in older ones.
B17: Regions follow the five URA planning regions (Central, East, North, North-East, West). Each playground is assigned to the nearest planning-area centroid, so boundary-area assignments are indicative rather than official.
B19: Scoping rules: playgrounds are included when they are publicly accessible outdoor (or public-facility indoor) play spaces. Condominium/private-school playgrounds are excluded where tagged private in OSM; mall playgrounds appear only in the Destination Playgrounds reference sheet and are flagged as privately managed.

Sheet Master Inventory
B2: Master Inventory — Every Accounted Playground Site
B4: ID | C4: Playground name | D4: Agency group | E4: Managing agency | F4: Location type | G4: Location (park / estate / place) | H4: Planning area (nearest) | I4: Region | J4: Latitude | K4: Longitude | L4: Name status | M4: Data source | N4: Notes
B5: A-001 | C5: ACLP PLAYGROUND | D5: A. NParks — Park Playgrounds | E5: National Parks Board | F5: Park playground | G5: (park not mapped) | H5: Bukit Merah | I5: Central | J5: 1.294551 | K5: 103.81225 | L5: Named | M5: NParks / data.gov.sg (official) | N5: 1 facility record(s) in cluster
B6: A-002 | C6: Aljunied Park Sandpit PG | D6: A. NParks — Park Playgrounds | E6: National Parks Board | F6: Park playground | G6: Aljunied Pk | H6: Geylang | I6: Central | J6: 1.329617 | K6: 103.88 | L6: Named | M6: NParks / data.gov.sg (official) | N6: 2 facility record(s) in cluster
B7: A-003 | C7: Arthur Park Playground | D7: A. NParks — Park Playgrounds | E7: National Parks Board | F7: Park playground | G7: Arthur Pk | H7: Marine Parade | I7: Central | J7: 1.30387 | K7: 103.88822 | L7: Named | M7: NParks / data.gov.sg (official) | N7: 1 facility record(s) in cluster
B8: A-004 | C8: Geylang PC Playground | D8: A. NParks — Park Playgrounds | E8: National Parks Board | F8: Park playground | G8: Arthur Pk | H8: Marine Parade | I8: Central | J8: 1.305876 | K8: 103.88859 | L8: Named | M8: NParks / data.gov.sg (official) | N8: 1 facility record(s) in cluster
B9: A-005 | C9: Playground (generic equipment record) | D9: A. NParks — Park Playgrounds | E9: National Parks Board | F9: Park playground | G9: Beng Wan Rd Pg | H9: Kallang | I9: Central | J9: 1.323323 | K9: 103.86546 | L9: Generic record | M9: NParks / data.gov.sg (official) | N9: 1 facility record(s) in cluster
B10: A-006 | C10: Playground (generic equipment record) | D10: A. NParks — Park Playgrounds | E10: National Parks Board | F10: Park playground | G10: Binchang Rise Pg | H10: Bishan | I10: Central | J10: 1.348755 | K10: 103.84036 | L10: Generic record | M10: NParks / data.gov.sg (official) | N10: 1 facility record(s) in cluster
B11: A-007 | C11: Playground (generic equipment record) | D11: A. NParks — Park Playgrounds | E11: National Parks Board | F11: Park playground | G11: Binchang Rise Pg | H11: Bishan | I11: Central | J11: 1.348677 | K11: 103.84363 | L11: Generic record | M11: NParks / data.gov.sg (official) | N11: 2 facility record(s) in cluster
B12: A-008 | C12: Playground (generic equipment record) | D12: A. NParks — Park Playgrounds | E12: National Parks Board | F12: Park playground | G12: Bougainvillea Pk | H12: Tanglin | I12: Central | J12: 1.326256 | K12: 103.80852 | L12: Generic record | M12: NParks / data.gov.sg (official) | N12: 1 facility record(s) in cluster
B13: A-009 | C13: Bunga Rampai Park PG | D13: A. NParks — Park Playgrounds | E13: National Parks Board | F13: Park playground | G13: Bunga Rampai Pk | H13: Serangoon | I13: Central | J13: 1.340498 | K13: 103.88436 | L13: Named | M13: NParks / data.gov.sg (official) | N13: 1 facility record(s) in cluster
B14: A-010 | C14: Playground (generic equipment record) | D14: A. NParks — Park Playgrounds | E14: National Parks Board | F14: Park playground | G14: Butterfly Ave Pg | H14: Serangoon | I14: Central | J14: 1.334487 | K14: 103.87738 | L14: Generic record | M14: NParks / data.gov.sg (official) | N14: 1 facility record(s) in cluster
B15: A-011 | C15: Playround | D15: A. NParks — Park Playgrounds | E15: National Parks Board | F15: Park playground | G15: Cambridge Park | H15: Novena | I15: Central | J15: 1.313675 | K15: 103.84698 | L15: Named | M15: NParks / data.gov.sg (official) | N15: 1 facility record(s) in cluster
B16: A-012 | C16: Play Equipments | D16: A. NParks — Park Playgrounds | E16: National Parks Board | F16: Park playground | G16: Camp Road Interim Park | H16: Tanglin | I16: Central | J16: 1.302415 | K16: 103.81884 | L16: Named | M16: NParks / data.gov.sg (official) | N16: 2 facility record(s) in cluster
... B351: B-0003 | C351: (Unnamed playground) | D351: B. HDB & Town Councils — Estate Playgrounds | E351: Town Council (HDB estate) | F351: Estate playground | G351: Bishan (estate) | H351: Bishan | I351: Central | J351: 1.359411 | K351: 103.83214 | L351: Unnamed | M351: OpenStreetMap | N351: ~297 m from The Inglewood Pg
B352: B-0004 | C352: (Unnamed playground) | D352: B. HDB & Town Councils — Estate Playgrounds | E352: Town Council (HDB estate) | F352: Estate playground | G352: Bishan (estate) | H352: Bishan | I352: Central | J352: 1.349928 | K352: 103.83892 | L352: Unnamed | M352: OpenStreetMap
B353: B-0005 | C353: (Unnamed playground) | D353: B. HDB & Town Councils — Estate Playgrounds | E353: Town Council (HDB estate) | F353: Estate playground | G353: Bishan (estate) | H353: Bishan | I353: Central | J353: 1.357693 | K353: 103.83254 | L353: Unnamed | M353: OpenStreetMap | N353: ~209 m from Jalan Sembilang Park
B354: B-0006 | C354: (Unnamed playground) | D354: B. HDB & Town Councils — Estate Playgrounds | E354: Town Council (HDB estate) | F354: Estate playground | G354: Bishan (estate) | H354: Bishan | I354: Central | J354: 1.358511 | K354: 103.84324 | L354: Unnamed | M354: OpenStreetMap
B355: B-0007 | C355: (Unnamed playground) | D355: B. HDB & Town Councils — Estate Playgrounds | E355: Town Council (HDB estate) | F355: Estate playground | G355: Bishan (estate) | H355: Bishan | I355: Central | J355: 1.34905 | K355: 103.83865 | L355: Unnamed | M355: OpenStreetMap
B356: B-0008 | C356: (Unnamed playground) | D356: B. HDB & Town Councils — Estate Playgrounds | E356: Town Council (HDB estate) | F356: Estate playground | G356: Bishan (estate) | H356: Bishan | I356: Central | J356: 1.354735 | K356: 103.83731 | L356: Unnamed | M356: OpenStreetMap
B357: B-0009 | C357: (Unnamed playground) | D357: B. HDB & Town Councils — Estate Playgrounds | E357: Town Council (HDB estate) | F357: Estate playground | G357: Bishan (estate) | H357: Bishan | I357: Central | J357: 1.354812 | K357: 103.83761 | L357: Unnamed | M357: OpenStreetMap | N357: ~280 m from Jln Pintau Pg
B358: B-0010 | C358: (Unnamed playground) | D358: B. HDB & Town Councils — Estate Playgrounds | E358: Town Council (HDB estate) | F358: Estate playground | G358: Bishan (estate) | H358: Bishan | I358: Central | J358: 1.356371 | K358: 103.8283 | L358: Unnamed | M358: OpenStreetMap | N358: ~280 m from Venus Green
B359: B-0011 | C359: (Unnamed playground) | D359: B. HDB & Town Councils — Estate Playgrounds | E359: Town Council (HDB estate) | F359: Estate playground | G359: Bishan (estate) | H359: Bishan | I359: Central | J359: 1.345349 | K359: 103.848 | L359: Unnamed | M359: OpenStreetMap
B360: B-0012 | C360: (Unnamed playground) | D360: B. HDB & Town Councils — Estate Playgrounds | E360: Town Council (HDB estate) | F360: Estate playground | G360: Bishan (estate) | H360: Bishan | I360: Central | J360: 1.357226 | K360: 103.84717 | L360: Unnamed | M360: OpenStreetMap
B361: B-0013 | C361: (Unnamed playground) | D361: B. HDB & Town Councils — Estate Playgrounds | E361: Town Council (HDB estate) | F361: Estate playground | G361: Bishan (estate) | H361: Bishan | I361: Central | J361: 1.351901 | K361: 103.85376 | L361: Unnamed | M361: OpenStreetMap | N361: ~269 m from Kallang Linear Park
B362: B-0014 | C362: (Unnamed playground) | D362: B. HDB & Town Councils — Estate Playgrounds | E362: Town Council (HDB estate) | F362: Estate playground | G362: Bishan (estate) | H362: Bishan | I362: Central | J362: 1.352691 | K362: 103.85326 | L362: Unnamed | M362: OpenStreetMap
B363: B-0015 | C363: (Unnamed playground) | D363: B. HDB & Town Councils — Estate Playgrounds | E363: Town Council (HDB estate) | F363: Estate playground | G363: Bishan (estate) | H363: Bishan | I363: Central | J363: 1.351612 | K363: 103.85328 | L363: Unnamed | M363: OpenStreetMap | N363: ~298 m from Kallang Linear Park
B364: B-0016 | C364: (Unnamed playground) | D364: B. HDB & Town Councils — Estate Playgrounds | E364: Town Council (HDB estate) | F364: Estate playground | G364: Bishan (estate) | H364: Bishan | I364: Central | J364: 1.354386 | K364: 103.84441 | L364: Unnamed | M364: OpenStreetMap | N364: ~219 m from Pemimpin Place Pg
B365: B-0017 | C365: (Unnamed playground) | D365: B. HDB & Town Councils — Estate Playgrounds | E365: Town Council (HDB estate) | F365: Estate playground | G365: Bishan (estate) | H365: Bishan | I365: Central | J365: 1.346977 | K365: 103.84778 | L365: Unnamed | M365: OpenStreetMap
B366: B-0018 | C366: (Unnamed playground) | D366: B. HDB & Town Councils — Estate Playgrounds | E366: Town Council (HDB estate) | F366: Estate playground | G366: Bishan (estate) | H366: Bishan | I366: Central | J366: 1.347338 | K366: 103.84913 | L366: Unnamed | M366: OpenStreetMap
B367: B-0019 | C367: (Unnamed playground) | D367: B. HDB & Town Councils — Estate Playgrounds | E367: Town Council (HDB estate) | F367: Estate playground | G367: Bishan (estate) | H367: Bishan | I367: Central | J367: 1.347588 | K367: 103.84757 | L367: Unnamed | M367: OpenStreetMap
B368: B-0020 | C368: (Unnamed playground) | D368: B. HDB & Town Councils — Estate Playgrounds | E368: Town Council (HDB estate) | F368: Estate playground | G368: Bishan (estate) | H368: Bishan | I368: Central | J368: 1.352639 | K368: 103.85048 | L368: Unnamed | M368: OpenStreetMap
B369: B-0021 | C369: (Unnamed playground) | D369: B. HDB & Town Councils — Estate Playgrounds | E369: Town Council (HDB estate) | F369: Estate playground | G369: Bishan (estate) | H369: Bishan | I369: Central | J369: 1.349143 | K369: 103.84881 | L369: Unnamed | M369: OpenStreetMap
B370: B-0022 | C370: (Unnamed playground) | D370: B. HDB & Town Councils — Estate Playgrounds | E370: Town Council (HDB estate) | F370: Estate playground | G370: Bishan (estate) | H370: Bishan | I370: Central | J370: 1.349016 | K370: 103.84945 | L370: Unnamed | M370: OpenStreetMap
B371: B-0023 | C371: (Unnamed playground) | D371: B. HDB & Town Councils — Estate Playgrounds | E371: Town Council (HDB estate) | F371: Estate playground | G371: Bishan (estate) | H371: Bishan | I371: Central | J371: 1.348467 | K371: 103.8511 | L371: Unnamed | M371: OpenStreetMap
B372: B-0024 | C372: (Unnamed playground) | D372: B. HDB & Town Councils — Estate Playgrounds | E372: Town Council (HDB estate) | F372: Estate playground | G372: Bishan (estate) | H372: Bishan | I372: Central | J372: 1.350031 | K372: 103.85195 | L372: Unnamed | M372: OpenStreetMap
B373: B-0025 | C373: (Unnamed playground) | D373: B. HDB & Town Councils — Estate Playgrounds | E373: Town Council (HDB estate) | F373: Estate playground | G373: Bishan (estate) | H373: Bishan | I373: Central | J373: 1.349947 | K373: 103.85232 | L373: Unnamed | M373: OpenStreetMap
B374: B-0026 | C374: (Unnamed playground) | D374: B. HDB & Town Councils — Estate Playgrounds | E374: Town Council (HDB estate) | F374: Estate playground | G374: Bishan (estate) | H374: Bishan | I374: Central | J374: 1.349534 | K374: 103.85204 | L374: Unnamed | M374: OpenStreetMap
B375: B-0027 | C375: (Unnamed playground) | D375: B. HDB & Town Councils — Estate Playgrounds | E375: Town Council (HDB estate) | F375: Estate playground | G375: Bishan (estate) | H375: Bishan | I375: Central | J375: 1.348215 | K375: 103.85016 | L375: Unnamed | M375: OpenStreetMap
B376: B-0028 | C376: (Unnamed playground) | D376: B. HDB & Town Councils — Estate Playgrounds | E376: Town Council (HDB estate) | F376: Estate playground | G376: Bishan (estate) | H376: Bishan | I376: Central | J376: 1.348373 | K376: 103.85169 | L376: Unnamed | M376: OpenStreetMap
...

Sheet Group A - NParks (Parks)
B2: Group A — NParks Park Playgrounds (Official + Community-Mapped)
B4: Distinct playground sites in parks — 305 sites from 387 official facility records
B5: Site ID | C5: Site name (representative record) | D5: Parent park (nearest reference) | E5: Facility records | F5: Planning area (nearest) | G5: Region | H5: Latitude | I5: Longitude
B6: A-001 | C6: ACLP PLAYGROUND | D6: (park not mapped) | E6: 1 | F6: Bukit Merah | G6: Central | H6: 1.294551 | I6: 103.81225
B7: A-002 | C7: Aljunied Park Sandpit PG | D7: Aljunied Pk | E7: 2 | F7: Geylang | G7: Central | H7: 1.329617 | I7: 103.88
B8: A-003 | C8: Arthur Park Playground | D8: Arthur Pk | E8: 1 | F8: Marine Parade | G8: Central | H8: 1.30387 | I8: 103.88822
B9: A-004 | C9: Geylang PC Playground | D9: Arthur Pk | E9: 1 | F9: Marine Parade | G9: Central | H9: 1.305876 | I9: 103.88859
B10: A-005 | C10: Playground (generic equipment record) | D10: Beng Wan Rd Pg | E10: 1 | F10: Kallang | G10: Central | H10: 1.323323 | I10: 103.86546
B11: A-006 | C11: Playground (generic equipment record) | D11: Binchang Rise Pg | E11: 1 | F11: Bishan | G11: Central | H11: 1.348755 | I11: 103.84036
B12: A-007 | C12: Playground (generic equipment record) | D12: Binchang Rise Pg | E12: 2 | F12: Bishan | G12: Central | H12: 1.348677 | I12: 103.84363
B13: A-008 | C13: Playground (generic equipment record) | D13: Bougainvillea Pk | E13: 1 | F13: Tanglin | G13: Central | H13: 1.326256 | I13: 103.80852
B14: A-009 | C14: Bunga Rampai Park PG | D14: Bunga Rampai Pk | E14: 1 | F14: Serangoon | G14: Central | H14: 1.340498 | I14: 103.88436
B15: A-010 | C15: Playground (generic equipment record) | D15: Butterfly Ave Pg | E15: 1 | F15: Serangoon | G15: Central | H15: 1.334487 | I15: 103.87738
B16: A-011 | C16: Playround | D16: Cambridge Park | E16: 1 | F16: Novena | G16: Central | H16: 1.313675 | I16: 103.84698
B17: A-012 | C17: Play Equipments | D17: Camp Road Interim Park | E17: 2 | F17: Tanglin | G17: Central | H17: 1.302415 | I17: 103.81884
... B310: A-305 | C310: Yunnan Park PG | D310: Yunnan Park | E310: 1 | F310: Jurong West | G310: West | H310: 1.337246 | I310: 103.69297
B311: Total | E311: 387
B312: Official dataset lists playground equipment/facility points (e.g. 'Swing', 'Composite Play Equipment'); records within 40 m are clustered into one site. Representative name = most specific record in cluster.
B314: Additional community-mapped park playgrounds (OpenStreetMap) — not in the official facility export
B315: ID | C315: Name (OSM) | D315: Park (nearest reference) | E315: Planning area (nearest) | F315: Region | G315: Latitude | H315: Longitude
B316: A-X01 | C316: (Unnamed playground) | D316: Bidadari Park Hillock | E316: Serangoon | F316: Central | G316: 1.341401 | H316: 103.87245
B317: A-X02 | C317: (Unnamed playground) | D317: Bidadari Park Hillock | E317: Serangoon | F317: Central | G317: 1.342314 | H317: 103.87403
B318: A-X03 | C318: (Unnamed playground) | D318: Bidadari Park South | E318: Serangoon | F318: Central | G318: 1.338524 | H318: 103.87454
B319: A-X04 | C319: (Unnamed playground) | D319: Chwee Chian Playground | E319: Queenstown | F319: Central | G319: 1.280288 | H319: 103.78912
B320: A-X05 | C320: Eco-playground | D320: City Green | E320: Rochor | F320: Central | G320: 1.311679 | H320: 103.85607
B321: A-X06 | C321: (Unnamed playground) | D321: City Green | E321: Rochor | F321: Central | G321: 1.312127 | H321: 103.85623
B322: A-X07 | C322: (Unnamed playground) | D322: Dhoby Ghaut Green | E322: Museum | F322: Central | G322: 1.298643 | H322: 103.84505
B323: A-X08 | C323: whale of a Tale | D323: Farquhar Garden (Fcp) | E323: Museum | F323: Central | G323: 1.296225 | H323: 103.84923
B324: A-X09 | C324: Goldhill Avenue Playground | D324: Goldhill Ave Pg | E324: Newton | F324: Central | G324: 1.320988 | H324: 103.8331
B325: A-X10 | C325: (Unnamed playground) | D325: Goldhill Ave Pg | E325: Newton | F325: Central | G325: 1.321181 | H325: 103.83332
B326: A-X11 | C326: (Unnamed playground) | D326: Greenway South | E326: Serangoon | F326: Central | G326: 1.343252 | H326: 103.87784
B327: A-X12 | C327: Nature Playgarden | D327: Hortpark | E327: Queenstown | F327: Central | G327: 1.279632 | H327: 103.79795
... B354: A-X39 | C354: (Unnamed playground) | D354: Westwood Park Playground | E354: Jurong West | F354: West | G354: 1.352316 | H354: 103.70199
B357: All 387 official facility records (data.gov.sg 'Park Facilities')
B358: Record name (official dataset) | C358: Part of site | D358: Latitude | E358: Longitude | F358: Last updated (date part)
B359: 10013 | C359: 10013 | D359: 1.325465 | E359: 103.81777 | F359: 20260115
B360: 10013 | C360: 10013 | D360: 1.3243 | E360: 103.80554 | F360: 20260115
B361: 10013 | C361: 10013 | D361: 1.323249 | E361: 103.7965 | F361: 20260115
B362: 10020 | C362: 10020 | D362: 1.32216 | E362: 103.80188 | F362: 20260115
B363: 2-5 year old sandpit play set flooring | C363: 2-5 year old sandpit play set flooring | D363: 1.371789 | E363: 103.76365 | F363: 20260115
...

Sheet Group B - HDB & Town Councils
B2: Group B — HDB & Town Council Estate Playgrounds
B4: Estate playgrounds by planning area — 1754 community-mapped sites
B5: Planning area | C5: Region | D5: Sites | E5: Named | F5: Unnamed
B6: Sengkang | C6: North-East | D6: 120 | E6: 3 | F6: 117
B7: Punggol | C7: North-East | D7: 115 | E7: 4 | F7: 111
B8: Yishun | C8: North | D8: 96 | E8: 0 | F8: 96
B9: Toa Payoh | C9: Central | D9: 92 | E9: 4 | F9: 88
B10: Jurong West | C10: West | D10: 87 | E10: 2 | F10: 85
B11: Sembawang | C11: North | D11: 87 | E11: 3 | F11: 84
B12: Woodlands | C12: North | D12: 86 | E12: 1 | F12: 85
B13: Bedok | C13: East | D13: 85 | E13: 3 | F13: 82
B14: Bukit Gombak | C14: West | D14: 77 | E14: 1 | F14: 76
B15: Choa Chu Kang | C15: West | D15: 67 | E15: 2 | F15: 65
B16: Ang Mo Kio | C16: North-East | D16: 64 | E16: 3 | F16: 61
B17: Tampines | C17: East | D17: 63 | E17: 8 | F17: 55
... B51: Pioneer | C51: West | D51: 1 | E51: 0 | F51: 1
B52: Total | D52: 1754 | E52: 96 | F52: 1658
B53: Towns are planning areas (nearest-centroid assignment). Tengah, Punggol and Sengkang lead counts among newer towns — newer estates build more, and are mapped more densely by the community. Cross-check against HDB dwellings per town flags Hougang, Bukit Panjang and Tampines as the most likely undermapped towns (see Sources & Methodology — Completeness audit).
B55: Full estate listing — 1754 rows (names where mapped)
B56: ID | C56: Playground name | D56: Planning area | E56: Region | F56: Latitude | G56: Longitude | H56: Name status | I56: Nearby park (≤300 m) | J56: Operator tag | K56: Wheelchair tag
B57: B-0001 | C57: (Unnamed playground) | D57: Bishan | E57: Central | F57: 1.342118 | G57: 103.83508 | H57: Unnamed | I57: 200 m to Macritchie Reservoir Pk
B58: B-0002 | C58: (Unnamed playground) | D58: Bishan | E58: Central | F58: 1.358853 | G58: 103.83016 | H58: Unnamed | I58: 247 m to The Inglewood Pg
B59: B-0003 | C59: (Unnamed playground) | D59: Bishan | E59: Central | F59: 1.359411 | G59: 103.83214 | H59: Unnamed | I59: 297 m to The Inglewood Pg
B60: B-0004 | C60: (Unnamed playground) | D60: Bishan | E60: Central | F60: 1.349928 | G60: 103.83892 | H60: Unnamed
B61: B-0005 | C61: (Unnamed playground) | D61: Bishan | E61: Central | F61: 1.357693 | G61: 103.83254 | H61: Unnamed | I61: 209 m to Jalan Sembilang Park
B62: B-0006 | C62: (Unnamed playground) | D62: Bishan | E62: Central | F62: 1.358511 | G62: 103.84324 | H62: Unnamed
B63: B-0007 | C63: (Unnamed playground) | D63: Bishan | E63: Central | F63: 1.34905 | G63: 103.83865 | H63: Unnamed
B64: B-0008 | C64: (Unnamed playground) | D64: Bishan | E64: Central | F64: 1.354735 | G64: 103.83731 | H64: Unnamed
B65: B-0009 | C65: (Unnamed playground) | D65: Bishan | E65: Central | F65: 1.354812 | G65: 103.83761 | H65: Unnamed | I65: 280 m to Jln Pintau Pg
B66: B-0010 | C66: (Unnamed playground) | D66: Bishan | E66: Central | F66: 1.356371 | G66: 103.8283 | H66: Unnamed | I66: 280 m to Venus Green
B67: B-0011 | C67: (Unnamed playground) | D67: Bishan | E67: Central | F67: 1.345349 | G67: 103.848 | H67: Unnamed
B68: B-0012 | C68: (Unnamed playground) | D68: Bishan | E68: Central | F68: 1.357226 | G68: 103.84717 | H68: Unnamed
B69: B-0013 | C69: (Unnamed playground) | D69: Bishan | E69: Central | F69: 1.351901 | G69: 103.85376 | H69: Unnamed | I69: 269 m to Kallang Linear Park
B70: B-0014 | C70: (Unnamed playground) | D70: Bishan | E70: Central | F70: 1.352691 | G70: 103.85326 | H70: Unnamed
B71: B-0015 | C71: (Unnamed playground) | D71: Bishan | E71: Central | F71: 1.351612 | G71: 103.85328 | H71: Unnamed | I71: 298 m to Kallang Linear Park
B72: B-0016 | C72: (Unnamed playground) | D72: Bishan | E72: Central | F72: 1.354386 | G72: 103.84441 | H72: Unnamed | I72: 219 m to Pemimpin Place Pg
B73: B-0017 | C73: (Unnamed playground) | D73: Bishan | E73: Central | F73: 1.346977 | G73: 103.84778 | H73: Unnamed
B74: B-0018 | C74: (Unnamed playground) | D74: Bishan | E74: Central | F74: 1.347338 | G74: 103.84913 | H74: Unnamed
B75: B-0019 | C75: (Unnamed playground) | D75: Bishan | E75: Central | F75: 1.347588 | G75: 103.84757 | H75: Unnamed
B76: B-0020 | C76: (Unnamed playground) | D76: Bishan | E76: Central | F76: 1.352639 | G76: 103.85048 | H76: Unnamed
...

Sheet Group C - Other Public Agencies
B2: Group C — Other Public Agency Playgrounds & Play Spaces
B4: ID | C4: Name | D4: Managing agency | E4: Location type | F4: Location | G4: Planning area | H4: Region | I4: Latitude | J4: Longitude | K4: Notes
B5: C-01 | C5: Far East Organization Children's Garden | D5: Gardens by the Bay (statutory board) | E5: Children's garden / water play | F5: Bay South Garden, 18 Marina Gardens Dr | G5: Downtown Core | H5: Central | I5: 1.2812 | J5: 103.8702 | K5: Water fountains for older kids and toddlers, treehouses, rope walks, 130 m nature trail. Closed Mondays.
B6: C-02 | C6: PropNex Family Zone (Active Garden) | D6: Gardens by the Bay (statutory board) | E6: Inclusive playground | F6: Active Garden, Gardens by the Bay | G6: Downtown Core | H6: Central | I6: 1.2798 | J6: 103.8694 | K6: Twin 9 m Supertree-inspired towers that light up at night, sandpit with light projections, inclusive design.
B7: C-03 | C7: A Whale of a Tale (Magical Bridge Design) | D7: National Heritage Board | E7: Museum outdoor playground | F7: Front lawn, National Museum of Singapore, 93 Stamford Rd | G7: Museum | H7: Central | I7: 1.2966 | J7: 103.8486 | K7: Inclusive playground shaped like the museum's historic blue-whale skeleton.
B8: C-04 | C8: My Tree House @ Central Public Library | D8: National Library Board | E8: Indoor play zone | F8: Central Public Library, 100 Victoria St | G8: Museum | H8: Central | I8: 1.2949 | J8: 103.8539 | K8: Permanent indoor 'green treehouse' play space for children (play zone rather than play equipment).
B9: C-05 | C9: Play spaces @ Punggol Regional Library | D9: National Library Board | E9: Indoor play zone | F9: Punggol Regional Library, 1 Punggol Central | G9: Punggol | H9: North-East | I9: 1.4052 | J9: 103.9021 | K9: Themed children's play zones inside the regional library (indoor).
B10: C-06 | C10: Forest Gym Playground @ Bukit Canberra | D10: SportSG | E10: Outdoor nature gym playground | F10: Bukit Canberra, 12 Sembawang Way | G10: Sembawang | H10: North-East | I10: 1.443 | J10: 103.8182 | K10: Nature-integrated play-and-gym space within the SportSG Bukit Canberra integrated hub.
B11: C-07 | C11: The Oval @ Seletar Aerospace Park | D11: JTC Corporation | E11: Community green with playground | F11: 110 Seletar Aerospace Walk | G11: Seletar | H11: North-East | I11: 1.4185 | J11: 103.879 | K11: Aviation-themed community park with playground on the Seletar Aerospace Park lawn.
B12: C-08 | C12: ActiveSG water play zones at swimming complexes (aggregate) | D12: SportSG (ActiveSG) | E12: Water play at public pools (aggregate row) | F12: Selected ActiveSG swimming complexes, e.g. Jurong East, Pasir Ris, Sengkang, Toa Payoh | G12: Islandwide | H12: Islandwide | K12: Many ActiveSG swimming complexes include children's water-play zones; check myactivesg.com per complex. Pool entry fees apply.
B13: C-09 | C13: Community club playgrounds (aggregate) | D13: People's Association | E13: CC / integrated-hub playgrounds (aggregate row) | F13: Most of PA's 100+ community clubs and hubs (e.g. Our Tampines Hub) | G13: Islandwide | H13: Islandwide | K13: No public master list; most community clubs include a playground or play corner. Check OnePA directory.
B14: C-10 | C14: Sentosa island playgrounds (aggregate) | D14: Sentosa Development Corporation (statutory board) | E14: Island attractions (aggregate row) | F14: Palawan Beach, Siloso Beach and Sentosa precincts | G14: Southern Islands | H14: Central | K14: Publicly accessible playgrounds on Sentosa; island/beach admission and transport fees apply.
B18: Aggregate rows stand in for facility classes that agencies do not publish at address level (ActiveSG water-play zones, community club playgrounds, Sentosa island playgrounds). Consult the agency directories for specifics.

Sheet Group D - Community Centres
B2: Group D — People's Association Community Centres (Amenity Layer)
B4: ID | C4: Community club | D4: Site status | E4: Blk | F4: Street | G4: Postal | H4: Planning area | I4: Region | J4: Latitude | K4: Longitude | L4: Source record | M4: Notes
B5: D-001 | C5: Bishan CC | D5: operating | E5: 51 | F5: Bishan Street 13 | G5: 579799 | H5: Bishan | I5: Central | J5: 1.349512 | K5: 103.85051 | L5: PA 2024 | M5: playground mapped on/near site (≤150 m);
B6: D-002 | C6: Thomson CC | D6: operating | E6: 194 | F6: Upper Thomson Road | G6: 574339 | H6: Bishan | I6: Central | J6: 1.351254 | K6: 103.83626 | L6: PA 2024 | M6: redevelopment noted in PA 2023 record
B7: D-003 | C7: Bukit Merah CC | D7: operating | E7: 4000 | F7: Jalan Bukit Merah | G7: 159465 | H7: Bukit Merah | I7: Central | J7: 1.285254 | K7: 103.81583 | L7: PA 2023 | M7: playground mapped on/near site (≤150 m);
B8: D-004 | C8: Henderson CC | D8: operating | E8: 500 | F8: Bukit Merah View | G8: 159682 | H8: Bukit Merah | I8: Central | J8: 1.28601 | K8: 103.82331 | L8: PA 2024 | M8: playground mapped on/near site (≤150 m);
B9: D-005 | C9: Leng Kee CC | D9: operating | E9: 400 | F9: Lengkok Bahru | G9: 159049 | H9: Bukit Merah | I9: Central | J9: 1.289787 | K9: 103.81445 | L9: PA 2024
B10: D-006 | C10: Radin Mas CC | D10: operating | E10: 51 | F10: Telok Blangah Crescent | G10: 98917 | H10: Bukit Merah | I10: Central | J10: 1.275931 | K10: 103.81975 | L10: PA 2024 | M10: playground mapped on/near site (≤150 m);
B11: D-007 | C11: Telok Blangah CC | D11: operating | E11: 450 | F11: Telok Blangah Street 31 | G11: 108943 | H11: Bukit Merah | I11: Central | J11: 1.274863 | K11: 103.80787 | L11: PA 2024
B12: D-008 | C12: MacPherson CC | D12: operating | E12: 400 | F12: Paya Lebar Way | G12: 379131 | H12: Geylang | I12: Central | J12: 1.323537 | K12: 103.88448 | L12: PA 2024
B13: D-009 | C13: Mountbatten CC | D13: operating | E13: 87 | F13: Jalan Satu | G13: 390087 | H13: Geylang | I13: Central | J13: 1.309235 | K13: 103.88683 | L13: PA 2024 | M13: playground mapped on/near site (≤150 m); redevelopment noted in PA 2023 record
B14: D-010 | C14: Geylang West CC | D14: operating | E14: 1205 | F14: Upper Boon Keng Road | G14: 387311 | H14: Kallang | I14: Central | J14: 1.315691 | K14: 103.87239 | L14: PA 2024 | M14: playground mapped on/near site (≤150 m);
B15: D-011 | C15: Kallang CC | D15: operating | E15: 45 | F15: Boon Keng Road | G15: 339771 | H15: Kallang | I15: Central | J15: 1.317803 | K15: 103.86237 | L15: PA 2024
B16: D-012 | C16: Katong CC | D16: operating | E16: 51 | F16: Kampong Arang Road | G16: 438178 | H16: Kallang | I16: Central | J16: 1.300591 | K16: 103.88475 | L16: PA 2024
B17: D-013 | C17: Kolam Ayer CC | D17: operating | E17: 1 | F17: Geylang Bahru Lane | G17: 339631 | H17: Kallang | I17: Central | J17: 1.324154 | K17: 103.86969 | L17: PA 2024 | M17: playground mapped on/near site (≤150 m);
B18: D-014 | C18: Geylang Serai CC | D18: operating | E18: 1 | F18: Engku Aman Turn | G18: 408528 | H18: Marine Parade | I18: Central | J18: 1.316528 | K18: 103.89656 | L18: PA 2024
B19: D-015 | C19: Joo Chiat CC | D19: operating | E19: 405 | F19: Joo Chiat Road | G19: 427633 | H19: Marine Parade | I19: Central | J19: 1.307457 | K19: 103.90417 | L19: PA 2024
B20: D-016 | C20: Kampong Ubi CC | D20: operating | E20: 10 | F20: Jalan Ubi | G20: 409075 | H20: Marine Parade | I20: Central | J20: 1.317846 | K20: 103.90075 | L20: PA 2024
B21: D-017 | C21: Marine Parade CC | D21: operating (temp site) | E21: 67 | F21: Marine Drive | G21: 440067 | H21: Marine Parade | I21: Central | J21: 1.304457 | K21: 103.9096 | L21: PA 2024 | M21: redevelopment noted in PA 2023 record; main building being redeveloped; operating from temporary site
B22: D-018 | C22: Cairnhill CC | D22: operating | E22: 1 | F22: Anthony Road | G22: 229944 | H22: Newton | I22: Central | J22: 1.310434 | K22: 103.83886 | L22: PA 2024 | M22: playground mapped on/near site (≤150 m);
B23: D-019 | C23: Tanglin CC | D23: operating | E23: 245 | F23: Whitley Road | G23: 297829 | H23: Newton | I23: Central | J23: 1.323384 | K23: 103.82688 | L23: PA 2024
B24: D-020 | C24: Kreta Ayer CC | D24: operating | E24: 28A | F24: Kreta Ayer Road | G24: 88995 | H24: Outram | I24: Central | J24: 1.281193 | K24: 103.84301 | L24: PA 2024
B25: D-021 | C25: Tanjong Pagar CC | D25: operating | E25: 101 | F25: Cantonment Road | G25: 89774 | H25: Outram | I25: Central | J25: 1.276167 | K25: 103.84158 | L25: PA 2024
B26: D-022 | C26: Tiong Bahru CC | D26: operating | E26: 67A | F26: Eu Chin Street | G26: 169715 | H26: Outram | I26: Central | J26: 1.283453 | K26: 103.83188 | L26: PA 2024
B27: D-023 | C27: Buona Vista CC | D27: operating | E27: 36 | F27: Holland Drive | G27: 270036 | H27: Queenstown | I27: Central | J27: 1.309259 | K27: 103.79262 | L27: PA 2024 | M27: playground mapped on/near site (≤150 m);
B28: D-024 | C28: Dover CC | D28: operating | E28: 1 | F28: Dover Road | G28: 130001 | H28: Queenstown | I28: Central | J28: 1.30253 | K28: 103.78327 | L28: PA 2024 | M28: playground mapped on/near site (≤150 m);
B29: D-025 | C29: Queenstown CC | D29: operating | E29: 365 | F29: Commonwealth Avenue | G29: 149732 | H29: Queenstown | I29: Central | J29: 1.29915 | K29: 103.8013 | L29: PA 2024
B30: D-026 | C30: Ulu Pandan CC | D30: operating | E30: 170 | F30: Ghim Moh Road | G30: 279621 | H30: Queenstown | I30: Central | J30: 1.312009 | K30: 103.78921 | L30: PA 2024 | M30: playground mapped on/near site (≤150 m); redevelopment noted in PA 2023 record
B31: D-027 | C31: Jalan Besar CC | D31: operating | E31: 69 | F31: Jellicoe Road | G31: 208737 | H31: Rochor | I31: Central | J31: 1.308004 | K31: 103.86179 | L31: PA 2024 | M31: playground mapped on/near site (≤150 m);
B32: D-028 | C32: Kampong Glam CC | D32: operating | E32: 385 | F32: Beach Road | G32: 199581 | H32: Rochor | I32: Central | J32: 1.302795 | K32: 103.8636 | L32: PA 2024
B33: D-029 | C33: Pek Kio CC | D33: operating | E33: 21 | F33: Gloucester Road | G33: 219458 | H33: Rochor | I33: Central | J33: 1.313059 | K33: 103.85137 | L33: PA 2024 | M33: playground mapped on/near site (≤150 m);
B34: D-030 | C34: Bidadari CC | D34: operating | E34: 11 | F34: Bidadari Park Drive | G34: 367803 | H34: Serangoon | I34: Central | J34: 1.338731 | K34: 103.87167 | L34: PA 2024 | M34: playground mapped on/near site (≤150 m); redevelopment noted in PA 2023 record
B35: D-031 | C35: Braddell Heights CC | D35: operating | E35: 50 | F35: Serangoon Avenue 2 | G35: 556129 | H35: Serangoon | I35: Central | J35: 1.351612 | K35: 103.87037 | L35: PA 2024 | M35: redevelopment noted in PA 2023 record
B36: D-032 | C36: Potong Pasir CC | D36: operating | E36: 6 | F36: Potong Pasir Avenue 2 | G36: 358361 | H36: Serangoon | I36: Central | J36: 1.332536 | K36: 103.86704 | L36: PA 2024 | M36: playground mapped on/near site (≤150 m);
B37: D-033 | C37: Kim Seng CC | D37: operating | E37: 570 | F37: Havelock Road | G37: 169640 | H37: Singapore River | I37: Central | J37: 1.289683 | K37: 103.83071 | L37: PA 2023 | M37: playground mapped on/near site (≤150 m); new/rebuilt CC under construction (PA 2024 record)
B38: D-034 | C38: imPAct@Hong Lim Green | D38: operating | E38: 20 | F38: Upper Pickering Street | G38: 58284 | H38: Singapore River | I38: Central | J38: 1.286329 | K38: 103.84648 | L38: PA 2024
B39: D-035 | C39: Toa Payoh Central CC | D39: operating | E39: 93 | F39: Toa Payoh Central | G39: 319194 | H39: Toa Payoh | I39: Central | J39: 1.334935 | K39: 103.85021 | L39: PA 2024 | M39: playground mapped on/near site (≤150 m); redevelopment noted in PA 2023 record
B40: D-036 | C40: Toa Payoh East CC | D40: operating | E40: 160 | F40: Lorong 6 Toa Payoh | G40: 319380 | H40: Toa Payoh | I40: Central | J40: 1.336275 | K40: 103.8547 | L40: PA 2024
B41: D-037 | C41: Toa Payoh South CC | D41: operating | E41: 1999 | F41: Lorong 8 Toa Payoh | G41: 319258 | H41: Toa Payoh | I41: Central | J41: 1.33489 | K41: 103.85938 | L41: PA 2024
B42: D-038 | C42: Toa Payoh West CC | D42: operating | E42: 200 | F42: Lorong 2 Toa Payoh | G42: 319642 | H42: Toa Payoh | I42: Central | J42: 1.335383 | K42: 103.84483 | L42: PA 2024 | M42: playground mapped on/near site (≤150 m);
...

Sheet Destination Playgrounds
B2: Destination Playgrounds — Notable Free Playgrounds Worth a Trip
B4: # | C4: Playground | D4: Region | E4: Location | F4: Agency group | G4: Key play features | H4: Source
B5: 1 | C5: Playground at Marina Bay (Red Dot Design Museum) | D5: Central | E5: Next to Red Dot Design Museum, Marina Bay | F5: Publicly accessible (private precinct) | G5: 8-ft wide slide, suspended rope climbing structure, net obstacle jungle gym, grandparent 'hangout' swing (opened May 2026) | H5: Sassy Mama
B6: 2 | C6: A Whale of a Tale @ National Museum of Singapore | D6: Central | E6: 93 Stamford Rd, museum front lawn | F6: National Heritage Board | G6: Inclusive climbing structure shaped like the museum's 1900s blue-whale skeleton | H6: Sassy Mama
B7: 3 | C7: PropNex Family Zone @ Gardens by the Bay | D7: Central | E7: Active Garden, Gardens by the Bay | F7: Gardens by the Bay | G7: Twin 9 m Supertree towers lit at night, sandpit with light projections, slides, nets, swings, inclusive | H7: Sassy Mama
B8: 4 | C8: COMO Adventure Grove @ Singapore Botanic Gardens | D8: Central | E8: 5 Gallop Rd, Gallop Extension | F8: NParks | G8: 10 m hand-painted banyan tower, 4 m & 2.1 m tube slides, swings and hammocks | H8: Sassy Mama / NParks
B9: 5 | C9: Jacob Ballas Children's Garden @ Botanic Gardens | D9: Central | E9: 481 Bukit Timah Rd (kids-only entry) | F9: NParks | G9: Giant treehouse slides in sandpit, zip line, accessible trampoline, revamped water play; Asia's largest children's garden (4 ha); closed Mondays | H9: Sassy Mama / NParks
B10: 6 | C10: Far East Organization Children's Garden @ Gardens by the Bay | D10: Central | E10: 18 Marina Gardens Dr | F10: Gardens by the Bay | G10: Water playground (toddler + older kids zones), treehouses, rope walks, 130 m nature trail; closed Mondays | H10: Sassy Mama / NParks
B11: 7 | C11: Toa Payoh Dragon Playground (Blk 28 Lor 6) | D11: Central | E11: Blk 28 Toa Payoh Lorong 6, S(310028) | F11: HDB & Town Councils | G11: 1979 heritage mosaic playground by Khor Ean Ghee (HDB); terrazzo dragon head, climb-through steel-ring body, slide, sandpit — Singapore's last full dragon | H11: Sassy Mama / heritage sources
B12: 8 | C12: Toa Payoh Lorong 4 Playground (Blk 81) | D12: Central | E12: 81 Lorong 4 Toa Payoh, S(312080) | F12: HDB & Town Councils | G12: Four slides, tube slide, play tower, shadow-play elements, swings, seesaw | H12: Sassy Mama
B13: 9 | C13: Toa Payoh Crest Playground | D13: Central | E13: 131 Lorong 1 Toa Payoh, S(312131) | F13: HDB & Town Councils | G13: Spacious climbing ropes, hammock, netted rope bridges, two slides | H13: Sassy Mama
B14: 10 | C14: Toa Payoh Central Playground | D14: Central | E14: 175 Lor 2 Toa Payoh, S(310175) | F14: HDB & Town Councils | G14: Large climbing structure, toddler slides, interactive screen games, water-jet wet zone | H14: Sassy Mama
B15: 11 | C15: Bidadari Park Adventure Playground | D15: Central | E15: Bidadari Park Drive (via Woodleigh Mall) | F15: NParks | G15: Bird's-nest-themed adventure playground, towering climbing nets, steep slides, flying fox | H15: Sassy Mama
B16: 12 | C16: Play @ Heights Park (Toa Payoh Water Play Park) | D16: Central | E16: Blk 144 Toa Payoh Lorong 2 | F16: HDB & Town Councils | G16: Water-play ship with jets, water channel with sliding gates, sandpit, swings, flying fox, toddler zone, trampoline, showers | H16: Sassy Mama
... B95: 91 | C95: Casuarina Exploratory Play Area @ Coney Island Park | D95: North-East | E95: Coney Island Park (Pulau Serangoon) | F95: NParks | G95: Adventure play area built from upcycled logs and sand | H95: NParks
B98: Reference list compiled from NParks playground pages and the Sassy Mama '89 Best Free Outdoor Playgrounds' index (Sep 2026). Agency attribution '(verify agency)' where the editorial source does not name the managing body. Mall/attraction precinct playgrounds are publicly accessible but privately managed and are excluded from agency counts.

Sheet Review
B2: Review — Cross-Checks (live formulas)
B4: Check | C4: Expected | D4: Actual | E4: Status
B5: Master Inventory row count | C5: 2108 | D5: =COUNTA('Master Inventory'!B5:B2112) | E5: =IF(C5=D5,"PASS","FAIL")
B6: Group A rows (park layer) | C6: 344 | D6: =COUNTIF('Master Inventory'!D5:D2112,"A. NParks — Park Playgrounds") | E6: =IF(C6=D6,"PASS","FAIL")
B7: Group B rows (estate layer) | C7: 1754 | D7: =COUNTIF('Master Inventory'!D5:D2112,"B. HDB & Town Councils — Estate Playgrounds") | E7: =IF(C7=D7,"PASS","FAIL")
B8: Group C rows (other agencies) | C8: 10 | D8: =COUNTIF('Master Inventory'!D5:D2112,"C. Other Public Agencies") | E8: =IF(C8=D8,"PASS","FAIL")
B9: Central region sites | C9: 575 | D9: =COUNTIF('Master Inventory'!I5:I2112,"Central") | E9: =IF(C9=D9,"PASS","FAIL")
B10: East region sites | C10: 289 | D10: =COUNTIF('Master Inventory'!I5:I2112,"East") | E10: =IF(C10=D10,"PASS","FAIL")
B11: North region sites | C11: 315 | D11: =COUNTIF('Master Inventory'!I5:I2112,"North") | E11: =IF(C11=D11,"PASS","FAIL")
B12: North-East region sites | C12: 449 | D12: =COUNTIF('Master Inventory'!I5:I2112,"North-East") | E12: =IF(C12=D12,"PASS","FAIL")
B13: West region sites | C13: 478 | D13: =COUNTIF('Master Inventory'!I5:I2112,"West") | E13: =IF(C13=D13,"PASS","FAIL")
B14: Named estate playgrounds | C14: 96 | D14: =COUNTIF('Group B - HDB & Town Councils'!H57:H1810,"Named") | E14: =IF(C14=D14,"PASS","FAIL")
B15: Unnamed estate playgrounds | C15: 1658 | D15: =COUNTIF('Group B - HDB & Town Councils'!H57:H1810,"Unnamed") | E15: =IF(C15=D15,"PASS","FAIL")
B16: Group D rows (community centres) | C16: 119 | D16: =COUNTA('Group D - Community Centres'!B5:B123) | E16: =IF(C16=D16,"PASS","FAIL")
B17: Group D sites with mapped playground nearby | C17: 58 | D17: =COUNTIF('Group D - Community Centres'!M5:M123,"playground mapped*") | E17: =IF(C17=D17,"PASS","FAIL")
B19: Expected values were computed at build time from the same source data; Actual values are live formulas over the sheets. Every row must show PASS.

Sheet Sources & Methodology
B2: Sources & Methodology
B4: Data sources
B5: # | C5: Source | D5: Where | E5: What it contributes | F5: Retrieved | G5: Rights
B6: 1 | C6: NParks 'Park Facilities' dataset (PLAYGROUND class) | D6: data.gov.sg — dataset d_14d807e20158338fd578c2913953516e | E6: 387 playground facility records in parks under NParks purview (name, coordinates, last-updated) | F6: 17 Oct 2026 | G6: Official; © data.gov.sg / NParks
B7: 2 | C7: NParks 'Parks' dataset (park reference points) | D7: data.gov.sg — dataset d_0542d48f0991541706b58059381a6eca | E7: 462 park reference points used to attribute each playground to its parent park | F7: 17 Oct 2026 | G7: Official; © data.gov.sg / NParks
B8: 3 | C8: OpenStreetMap Singapore extract | D8: download.openstreetmap.fr/extracts/asia/singapore.osm.pbf | E8: 2,452 leisure=playground features (nodes, ways and multipolygon relations). After public-access filtering and deduplication: estate layer (1754) and community-mapped park playgrounds (39) | F8: 17 Oct 2026 | G8: © OpenStreetMap contributors, ODbL
B9: 4 | C9: NParks 'Playgrounds' activity page | D9: nparks.gov.sg/visit/activities/fun-children/playgrounds | E9: Official descriptions of flagship themed playgrounds (page 1: 9 destinations) | F9: 17 Oct 2026 | G9: Official
B10: 5 | C10: Sassy Mama '89 Best Free Outdoor Playgrounds in Singapore' (updated Sep 2026) | D10: sassymamasg.com/play-best-outdoor-playgrounds-singapore-free | E10: Regional index of ~89 notable free playgrounds + feature descriptions; basis of the Destination Playgrounds sheet | F10: 17 Oct 2026 | G10: Editorial; names and locations cross-checked where possible
B11: 6 | C11: Ministry of National Development parliamentary answers; agency sites (Gardens by the Bay, SportSG, PA, JTC, NHB, NLB, SDC) | D11: mnd.gov.sg; agency websites | E11: Context for agency responsibilities; curated Group C rows | F11: 17 Oct 2026 | G11: Official
B12: 7 | C12: HDB published count tables: 'Cumulative HDB, Government or Institutional Facilities Since 1960'; 'Cumulative Shops and Recreational Facilities'; 'Dwelling Units under HDB's Management, by Town' | D12: data.gov.sg — collections 188 and 165 | E12: Completeness cross-check: playgrounds are not tracked as a category in any HDB table; dwellings-per-town feeds the density cross-check below | F12: 17 Oct 2026 | G12: Official
B13: 8 | C13: SLA 'National Map Polygon' and HPB 'Parks@SG' datasets | D13: data.gov.sg — d_29f066d67df3eae91df8a42f443863c8; d_99b71f5d34cf57a3a592fbfdef1f42b6 | E13: Completeness audit: both downloaded and scanned — no playground layer/entries exist in either | F13: 17 Oct 2026 | G13: Official
B14: 9 | C14: People's Association 'Community Clubs' and 'Community Club / PAssion WaVe Outlet' datasets | D14: data.gov.sg — d_f706de1427279e61fe41e89e24d440fa; d_9de02d3fb33d96da1855f4fbef549a0f | E14: Group D: 125 (2023) + 128 (2024) official PA records merge to 119 distinct community clubs at current operating sites, plus 6 PAssion WaVe outlets and 5 co-located outposts footnoted separately | F14: 17 Oct 2026 | G14: Official; © data.gov.sg / People's Association
B17: Methodology
B18: Step 1. Filter: OSM playgrounds tagged access=private/no/customers, and preschool-operated ones, are dropped as non-public (172 removed).
B19: Step 2. Geofence: every OSM point is tested against SLA National Map polygons — 12 features lying outside Singapore territory (11 on the Johor, Malaysia side of the border and 1 offshore in the Straits of Johor, artifacts of the OSM extract's cross-border buffer) are excluded (2,268 remain).
B20: Step 3. Deduplicate: OSM points within 30 m of each other merge to one (2,016 remain); OSM points within 60 m of an official NParks site are absorbed into the park layer to avoid double counting.
B21: Step 4. Cluster: the 387 official NParks facility records are union-find clustered within 40 m into 305 distinct playground sites; each site takes the most specific record name as its representative label.
B22: Step 5. Attribute: every site is matched to its nearest park reference point (≤800 m) for the parent-park field, and to the nearest planning-area centroid for planning area and URA region. Park extras = OSM points within 120 m of a park reference point.
B23: Step 6. Categorize: the three playground groups (A/B/C) follow who manages the ground the playground sits on; 'aggregate' rows cover facility classes no agency publishes at address level.
B24: Step 7. Community centres (Group D): the two official PA datasets (2023 KML vintage and the 2024 refresh that adds PAssion WaVe outlets and outposts) are merged to one record per club at its current operating site — plain record wins over (Temp Office), which wins over (U/C); status suffixes are stripped for matching, the renamed Yishun Link CC is matched to Nee Soon Link CC by coordinates, and every site is geofence-tested against SLA polygons.
B25: Step 8. Verify: the Review sheet re-derives every headline count live from the Master Inventory and Group B sheets — all rows must read PASS.
B28: Completeness audit — what else was checked (17 Oct 2026)
B29: Check | C29: How | D29: Result
B30: data.gov.sg full catalog | C30: All 4,670 datasets and 1,370 collections crawled via the public API | D30: NParks 'Park Facilities' is the only playground location dataset published by any Singapore agency — used in full
B31: SLA 'National Map Polygon' | C31: 7.7 MB SLA base-map layer incl. recreational features, downloaded and scanned | D31: 1,434 polygons cover hydrographic, coastal and park outlines only — no playground layer exists
B32: HPB 'Parks@SG' | C32: 52-venue GeoJSON, downloaded and scanned | D32: Park and fitness-corner venues only — no playground entries
B33: HDB count tables | C33: 'Facilities Completed Since 1960', 'Shops and Recreational Facilities', 'Dwelling Units by Town' scanned | D33: HDB does not track playgrounds as a category — confirms no official estate playground registry exists
B34: OneMap thematic API | C34: Checked via API (public themes require a personal token issued after free registration) | D34: Not usable in this environment; its point-of-interest layers mirror the same agency datasets already used
B35: OSM multipolygon relations | C35: Re-extraction extended beyond nodes/ways to relations (2,452 features total) | D35: 4 additional features found; all tagged private/preschool and correctly excluded — no public sites missed
B36: Geofence QA (SLA border test) | C36: Point-in-polygon test of every coordinate against SLA National Map polygons (Malaysia-side land is explicitly labelled 'JOHOR (MALAYSIA)') | D36: 12 artifacts of the OSM extract's cross-border buffer found and removed: 11 playgrounds inside Johor (4 near the Causeway, 4 along the Woodlands–Mandai straits, 3 near the Second Link) and 1 offshore in the straits
B37: Density cross-check | C37: Estate playgrounds per HDB town vs HDB dwelling units per town | D37: Peer median 1.57 playgrounds per 1,000 units; Hougang (0.75), Bukit Panjang (0.68), Tampines (0.84) and Kallang/Whampoa (0.90) map thin and are the most likely residual gaps
B39: Bottom line: the park layer (Groups A/C) is official and exhaustive; the estate layer (Group B) is the most complete public geocoded compilation available, with residual gaps concentrated in a few older towns named above.
B41: Known limitations
B42: • No agency publishes a complete register of estate playgrounds; the estate layer is community-mapped and therefore indicative — likely within ±20% of the true count, denser in newer towns (Tengah, Punggol, Sengkang) and sparser in older ones. The density cross-check (above) flags Hougang, Bukit Panjang, Tampines and Kallang/Whampoa as the most likely undermapped towns.
B43: • Region and planning-area fields use nearest-centroid assignment; rows near planning-area borders may sit in the adjacent area.
B44: • The official NParks export mixes site-level and equipment-level records; clustering to sites removes double counting but a handful of closely spaced equipment clusters may merge sites that are technically distinct.
B45: • Group C aggregate rows (ActiveSG water-play zones, community-club playgrounds, Sentosa) are scope markers, not exhaustive facility lists; per-facility detail is available from the respective agency directories.
B46: • Group D reflects the official PA datasets as published (2023/2024 refresh); clubs recorded only as (U/C) in both vintages appear at the future site, and clubs operating from temporary premises are pinned there until PA publishes the reopened site. Planning areas for CCs use the same nearest-centroid convention as the playground layers.
B47: • Destination Playgrounds is an editorial reference list — a few entries carry '(verify agency)' where the source does not name the managing body; block numbers for heritage mosaic playgrounds beyond the Toa Payoh dragon should be verified on site.
